<robot
  name="valter">
  <link
    name="Base">
    <inertial>
      <origin
        xyz="-0.085772 0.0020275 0.41776"
        rpy="0 0 0" />
      <mass
        value="12.623" />
      <inertia
        ixx="0.62246"
        ixy="0.0068498"
        ixz="-0.080685"
        iyy="0.91417"
        iyz="0.00087783"
        izz="0.63527" />
    </inertial>
    <visual>
      <origin
        xyz="0 0 0"
        rpy="0 0 0" />
      <geometry>
        <mesh
          filename="package://valter/meshes/Base.STL" />
      </geometry>
      <material
        name="">
        <color
          rgba="0.79608 0.82353 0.93725 1" />
      </material>
    </visual>
    <collision>
      <origin
        xyz="0 0 0"
        rpy="0 0 0" />
      <geometry>
        <mesh
          filename="package://valter/meshes/Base.STL" />
      </geometry>
    </collision>
  </link>
  <link
    name="RWheel">
    <inertial>
      <origin
        xyz="-5.9089E-18 -0.04 2.7756E-17"
        rpy="0 0 0" />
      <mass
        value="3.6203" />
      <inertia
        ixx="0.02066"
        ixy="1.4456E-19"
        ixz="7.4988E-37"
        iyy="0.037885"
        iyz="-4.5688E-35"
        izz="0.02066" />
    </inertial>
    <visual>
      <origin
        xyz="0 0 0"
        rpy="0 0 0" />
      <geometry>
        <mesh
          filename="package://valter/meshes/RWheel.STL" />
      </geometry>
      <material
        name="">
        <color
          rgba="0.29412 0.29412 0.29412 1" />
      </material>
    </visual>
    <collision>
      <origin
        xyz="0 0 0"
        rpy="0 0 0" />
      <geometry>
        <mesh
          filename="package://valter/meshes/RWheel.STL" />
      </geometry>
    </collision>
  </link>
  <joint
    name="RWheelAxis"
    type="continuous">
    <origin
      xyz="0.000341577688738742 -0.153675665570238 0.14"
      rpy="-6.12303176911189E-17 0 0" />
    <parent
      link="Base" />
    <child
      link="RWheel" />
    <axis
      xyz="0 1 0" />
  </joint>
  <link
    name="rwheel_centers">
    <inertial>
      <origin
        xyz="-7.58941520739853E-19 0.032994484499226 2.77555756156289E-17"
        rpy="0 0 0" />
      <mass
        value="0.0783773140784392" />
      <inertia
        ixx="5.85727895452635E-05"
        ixy="-9.93439486155924E-22"
        ixz="6.74972677106587E-22"
        iyy="7.03620982427163E-05"
        iyz="-1.28565220595161E-21"
        izz="5.85727895452635E-05" />
    </inertial>
    <visual>
      <origin
        xyz="0 0 0"
        rpy="0 0 0" />
      <geometry>
        <mesh
          filename="package://valter/meshes/rwheel_centers.STL" />
      </geometry>
      <material
        name="">
        <color
          rgba="0.796078431372549 0.823529411764706 0.937254901960784 1" />
      </material>
    </visual>
    <collision>
      <origin
        xyz="0 0 0"
        rpy="0 0 0" />
      <geometry>
        <mesh
          filename="package://valter/meshes/rwheel_centers.STL" />
      </geometry>
    </collision>
  </link>
  <joint
    name="rwheel_centers_fixed"
    type="fixed">
    <origin
      xyz="0 -0.00181724367610836 0"
      rpy="3.14159265358979 0 0" />
    <parent
      link="RWheel" />
    <child
      link="rwheel_centers" />
    <axis
      xyz="0 1 0" />
  </joint>
  <link
    name="LWheel">
    <inertial>
      <origin
        xyz="-2.7756E-17 -0.04 2.7756E-17"
        rpy="0 0 0" />
      <mass
        value="3.6203" />
      <inertia
        ixx="0.02066"
        ixy="-3.727E-19"
        ixz="-4.3368E-19"
        iyy="0.037885"
        iyz="-7.6303E-20"
        izz="0.02066" />
    </inertial>
    <visual>
      <origin
        xyz="0 0 0"
        rpy="0 0 0" />
      <geometry>
        <mesh
          filename="package://valter/meshes/LWheel.STL" />
      </geometry>
      <material
        name="">
        <color
          rgba="0.29412 0.29412 0.29412 1" />
      </material>
    </visual>
    <collision>
      <origin
        xyz="0 0 0"
        rpy="0 0 0" />
      <geometry>
        <mesh
          filename="package://valter/meshes/LWheel.STL" />
      </geometry>
    </collision>
  </link>
  <joint
    name="LWheelAxis"
    type="continuous">
    <origin
      xyz="0.000341577688738742 0.154324334429763 0.14"
      rpy="6.6286088844449E-17 0.39309481042652 -3.14159265358979" />
    <parent
      link="Base" />
    <child
      link="LWheel" />
    <axis
      xyz="0 -1 0" />
  </joint>
  <link
    name="lwheel_centers">
    <inertial>
      <origin
        xyz="-1.38777878078145E-17 -0.032994484499226 0"
        rpy="0 0 0" />
      <mass
        value="0.0783773140784395" />
      <inertia
        ixx="5.85727895452638E-05"
        ixy="9.55447513108561E-21"
        ixz="3.3881317890172E-21"
        iyy="7.03620982427168E-05"
        iyz="1.01107609647439E-20"
        izz="5.85727895452638E-05" />
    </inertial>
    <visual>
      <origin
        xyz="0 0 0"
        rpy="0 0 0" />
      <geometry>
        <mesh
          filename="package://valter/meshes/lwheel_centers.STL" />
      </geometry>
      <material
        name="">
        <color
          rgba="0.796078431372549 0.823529411764706 0.937254901960784 1" />
      </material>
    </visual>
    <collision>
      <origin
        xyz="0 0 0"
        rpy="0 0 0" />
      <geometry>
        <mesh
          filename="package://valter/meshes/lwheel_centers.STL" />
      </geometry>
    </collision>
  </link>
  <joint
    name="lwheel_centers_fixed"
    type="fixed">
    <origin
      xyz="0 -0.00181724367610836 0"
      rpy="0 -1.66371525153719E-34 0" />
    <parent
      link="LWheel" />
    <child
      link="lwheel_centers" />
    <axis
      xyz="0 1 0" />
  </joint>
  <link
    name="support_wheels">
    <inertial>
      <origin
        xyz="-0.21907 -1.3878E-17 -0.11182"
        rpy="0 0 0" />
      <mass
        value="1.3079" />
      <inertia
        ixx="0.018036"
        ixy="-1.3254E-18"
        ixz="0"
        iyy="0.080803"
        iyz="3.3826E-19"
        izz="0.065858" />
    </inertial>
    <visual>
      <origin
        xyz="0 0 0"
        rpy="0 0 0" />
      <geometry>
        <mesh
          filename="package://valter/meshes/support_wheels.STL" />
      </geometry>
      <material
        name="">
        <color
          rgba="0.25098 0.25098 0.25098 1" />
      </material>
    </visual>
    <collision>
      <origin
        xyz="0 0 0"
        rpy="0 0 0" />
      <geometry>
        <mesh
          filename="package://valter/meshes/support_wheels.STL" />
      </geometry>
    </collision>
  </link>
  <joint
    name="support_wheels_fixed"
    type="fixed">
    <origin
      xyz="0.189234607270609 -0.11129709785824 0.0679256801186866"
      rpy="1.5707963267949 0 0" />
    <parent
      link="Base" />
    <child
      link="support_wheels" />
    <axis
      xyz="0 0 0" />
  </joint>
  <link
    name="support_wheels_centers">
    <inertial>
      <origin
        xyz="-0.219066879644595 0 0.110556114336065"
        rpy="0 0 0" />
      <mass
        value="0.101015328916835" />
      <inertia
        ixx="0.00129045558161767"
        ixy="-1.00192180900982E-19"
        ixz="-5.14996031930615E-19"
        iyy="0.00613821129438006"
        iyz="-4.08388009196805E-20"
        izz="0.00487802902064206" />
    </inertial>
    <visual>
      <origin
        xyz="0 0 0"
        rpy="0 0 0" />
      <geometry>
        <mesh
          filename="package://valter/meshes/support_wheels_centers.STL" />
      </geometry>
      <material
        name="">
        <color
          rgba="0.796078431372549 0.823529411764706 0.937254901960784 1" />
      </material>
    </visual>
    <collision>
      <origin
        xyz="0 0 0"
        rpy="0 0 0" />
      <geometry>
        <mesh
          filename="package://valter/meshes/support_wheels_centers.STL" />
      </geometry>
    </collision>
  </link>
  <joint
    name="support_wheels_centers_fixed"
    type="fixed">
    <origin
      xyz="0 0 -0.222438597166117"
      rpy="0 0 0" />
    <parent
      link="support_wheels" />
    <child
      link="support_wheels_centers" />
    <axis
      xyz="0 0 0" />
  </joint>
  <link
    name="ManipulatorBase">
    <inertial>
      <origin
        xyz="0.075727 -0.0090419 -0.035"
        rpy="0 0 0" />
      <mass
        value="0.17883" />
      <inertia
        ixx="0.00017475"
        ixy="3.7501E-21"
        ixz="-2.3019E-20"
        iyy="0.0004071"
        iyz="3.531E-21"
        izz="0.00025942" />
    </inertial>
    <visual>
      <origin
        xyz="0 0 0"
        rpy="0 0 0" />
      <geometry>
        <mesh
          filename="package://valter/meshes/ManipulatorBase.STL" />
      </geometry>
      <material
        name="">
        <color
          rgba="0.79608 0.82353 0.93725 1" />
      </material>
    </visual>
    <collision>
      <origin
        xyz="0 0 0"
        rpy="0 0 0" />
      <geometry>
        <mesh
          filename="package://valter/meshes/ManipulatorBase.STL" />
      </geometry>
    </collision>
  </link>
  <joint
    name="ManipulatorBaseFixed"
    type="fixed">
    <origin
      xyz="0.157269945428792 0.0354609509421621 0.707041900761443"
      rpy="1.5707963267949 0 3.14159265358979" />
    <parent
      link="Base" />
    <child
      link="ManipulatorBase" />
    <axis
      xyz="0 0 0" />
  </joint>
  <link
    name="ManipulatorLink1">
    <inertial>
      <origin
        xyz="0.0084271 -0.29887 0.034995"
        rpy="0 0 0" />
      <mass
        value="4" />
      <inertia
        ixx="0.013436"
        ixy="-0.00089216"
        ixz="-1.6445E-10"
        iyy="0.0004086"
        iyz="5.7508E-09"
        izz="0.013731" />
    </inertial>
    <visual>
      <origin
        xyz="0 0 0"
        rpy="0 0 0" />
      <geometry>
        <mesh
          filename="package://valter/meshes/ManipulatorLink1.STL" />
      </geometry>
      <material
        name="">
        <color
          rgba="0.79216 0.81961 0.93333 1" />
      </material>
    </visual>
    <collision>
      <origin
        xyz="0 0 0"
        rpy="0 0 0" />
      <geometry>
        <mesh
          filename="package://valter/meshes/ManipulatorLink1.STL" />
      </geometry>
    </collision>
  </link>
  <joint
    name="ManipulatorLink1Axis"
    type="revolute">
    <origin
      xyz="0.015824 -0.0090419 0"
      rpy="3.1416 0 3.1416" />
    <parent
      link="ManipulatorBase" />
    <child
      link="ManipulatorLink1" />
    <axis
      xyz="0 0 -1" />
    <limit
      lower="-1"
      upper="0"
      effort="0"
      velocity="0" />
  </joint>
  <link
    name="ManipulatorLink2">
    <inertial>
      <origin
        xyz="-0.0019648 0.34838 0.034995"
        rpy="0 0 0" />
      <mass
        value="2" />
      <inertia
        ixx="0.0077703"
        ixy="-0.00010965"
        ixz="-4.7931E-12"
        iyy="0.000301"
        iyz="2.8093E-10"
        izz="0.007534" />
    </inertial>
    <visual>
      <origin
        xyz="0 0 0"
        rpy="0 0 0" />
      <geometry>
        <mesh
          filename="package://valter/meshes/ManipulatorLink2.STL" />
      </geometry>
      <material
        name="">
        <color
          rgba="0.79216 0.81961 0.93333 1" />
      </material>
    </visual>
    <collision>
      <origin
        xyz="0 0 0"
        rpy="0 0 0" />
      <geometry>
        <mesh
          filename="package://valter/meshes/ManipulatorLink2.STL" />
      </geometry>
    </collision>
  </link>
  <joint
    name="ManipulatorLink2Axis"
    type="revolute">
    <origin
      xyz="0.10656 -0.49054 0"
      rpy="0 0 0" />
    <parent
      link="ManipulatorLink1" />
    <child
      link="ManipulatorLink2" />
    <axis
      xyz="0 0 -1" />
    <limit
      lower="0"
      upper="1"
      effort="0"
      velocity="0" />
  </joint>
  <link
    name="ManipulatorLink3">
    <inertial>
      <origin
        xyz="-0.0046526 -0.021945 0.034995"
        rpy="0 0 0" />
      <mass
        value="0.22788" />
      <inertia
        ixx="0.00019702"
        ixy="4.0348E-05"
        ixz="-2.4752E-12"
        iyy="0.00015328"
        iyz="3.0548E-12"
        izz="0.00021369" />
    </inertial>
    <visual>
      <origin
        xyz="0 0 0"
        rpy="0 0 0" />
      <geometry>
        <mesh
          filename="package://valter/meshes/ManipulatorLink3.STL" />
      </geometry>
      <material
        name="">
        <color
          rgba="0.39216 0.39216 0.39216 1" />
      </material>
    </visual>
    <collision>
      <origin
        xyz="0 0 0"
        rpy="0 0 0" />
      <geometry>
        <mesh
          filename="package://valter/meshes/ManipulatorLink3.STL" />
      </geometry>
    </collision>
  </link>
  <joint
    name="ManipulatorLink3Axis"
    type="revolute">
    <origin
      xyz="-0.012962 0.55415 0"
      rpy="0 0 0" />
    <parent
      link="ManipulatorLink2" />
    <child
      link="ManipulatorLink3" />
    <axis
      xyz="0 0 -1" />
    <limit
      lower="-0.5"
      upper="1"
      effort="0"
      velocity="0" />
  </joint>
</robot>