<robot
  name="valter">
  <link
    name="Base">
    <inertial>
      <origin
        xyz="-0.0857715206977578 0.00202750279877116 0.417759281041388"
        rpy="0 0 0" />
      <mass
        value="12.6233325032135" />
      <inertia
        ixx="0.622457706177705"
        ixy="0.00684983540071118"
        ixz="-0.0806846238754764"
        iyy="0.914165189645381"
        iyz="0.000877831452103835"
        izz="0.635271744172888" />
    </inertial>
    <visual>
      <origin
        xyz="0 0 0"
        rpy="0 0 0" />
      <geometry>
        <mesh
          filename="package://valter/meshes/Base.STL" />
      </geometry>
      <material
        name="">
        <color
          rgba="0.796078431372549 0.823529411764706 0.937254901960784 1" />
      </material>
    </visual>
    <collision>
      <origin
        xyz="0 0 0"
        rpy="0 0 0" />
      <geometry>
        <mesh
          filename="package://valter/meshes/Base.STL" />
      </geometry>
    </collision>
  </link>
  <link
    name="RWheel">
    <inertial>
      <origin
        xyz="-5.908901840046E-18 -0.04 2.77555756156289E-17"
        rpy="0 0 0" />
      <mass
        value="3.62031355964479" />
      <inertia
        ixx="0.020659903156417"
        ixy="1.44560289664734E-19"
        ixz="7.49879891330915E-37"
        iyy="0.0378846933725851"
        iyz="-4.56881253081795E-35"
        izz="0.020659903156417" />
    </inertial>
    <visual>
      <origin
        xyz="0 0 0"
        rpy="0 0 0" />
      <geometry>
        <mesh
          filename="package://valter/meshes/RWheel.STL" />
      </geometry>
      <material
        name="">
        <color
          rgba="0.294117647058824 0.294117647058824 0.294117647058824 1" />
      </material>
    </visual>
    <collision>
      <origin
        xyz="0 0 0"
        rpy="0 0 0" />
      <geometry>
        <mesh
          filename="package://valter/meshes/RWheel.STL" />
      </geometry>
    </collision>
  </link>
  <joint
    name="RWheelAxis"
    type="continuous">
    <origin
      xyz="0.000341577688738742 -0.153675665570238 0.14"
      rpy="-6.12303176911189E-17 0 0" />
    <parent
      link="Base" />
    <child
      link="RWheel" />
    <axis
      xyz="0 1 0" />
  </joint>
  <link
    name="rwheel_centers">
    <inertial>
      <origin
        xyz="-8.13151629364128E-19 0.032994484499226 0"
        rpy="0 0 0" />
      <mass
        value="0.0783773140784392" />
      <inertia
        ixx="5.85727895452634E-05"
        ixy="-9.93439486155922E-22"
        ixz="6.74972677106586E-22"
        iyy="7.03620982427163E-05"
        iyz="5.91608801681983E-21"
        izz="5.85727895452635E-05" />
    </inertial>
    <visual>
      <origin
        xyz="0 0 0"
        rpy="0 0 0" />
      <geometry>
        <mesh
          filename="package://valter/meshes/rwheel_centers.STL" />
      </geometry>
      <material
        name="">
        <color
          rgba="0.796078431372549 0.823529411764706 0.937254901960784 1" />
      </material>
    </visual>
    <collision>
      <origin
        xyz="0 0 0"
        rpy="0 0 0" />
      <geometry>
        <mesh
          filename="package://valter/meshes/rwheel_centers.STL" />
      </geometry>
    </collision>
  </link>
  <joint
    name="rwheel_centers_fixed"
    type="fixed">
    <origin
      xyz="0 -0.00181724367610836 0"
      rpy="3.14159265358979 0 0" />
    <parent
      link="RWheel" />
    <child
      link="rwheel_centers" />
    <axis
      xyz="0 1 0" />
  </joint>
  <link
    name="LWheel">
    <inertial>
      <origin
        xyz="-2.77555756156289E-17 -0.04 2.77555756156289E-17"
        rpy="0 0 0" />
      <mass
        value="3.62031355964479" />
      <inertia
        ixx="0.020659903156417"
        ixy="-3.72702116811453E-19"
        ixz="-4.33680868994202E-19"
        iyy="0.0378846933725851"
        iyz="-7.63027965878358E-20"
        izz="0.020659903156417" />
    </inertial>
    <visual>
      <origin
        xyz="0 0 0"
        rpy="0 0 0" />
      <geometry>
        <mesh
          filename="package://valter/meshes/LWheel.STL" />
      </geometry>
      <material
        name="">
        <color
          rgba="0.294117647058824 0.294117647058824 0.294117647058824 1" />
      </material>
    </visual>
    <collision>
      <origin
        xyz="0 0 0"
        rpy="0 0 0" />
      <geometry>
        <mesh
          filename="package://valter/meshes/LWheel.STL" />
      </geometry>
    </collision>
  </link>
  <joint
    name="LWheelAxis"
    type="continuous">
    <origin
      xyz="0.000341577688738742 0.154324334429763 0.14"
      rpy="6.6286088844449E-17 0.39309481042652 -3.14159265358979" />
    <parent
      link="Base" />
    <child
      link="LWheel" />
    <axis
      xyz="0 -1 0" />
  </joint>
  <link
    name="lwheel_centers">
    <inertial>
      <origin
        xyz="-1.38777878078145E-17 -0.032994484499226 0"
        rpy="0 0 0" />
      <mass
        value="0.0783773140784395" />
      <inertia
        ixx="5.85727895452638E-05"
        ixy="6.79585568242382E-21"
        ixz="3.3881317890172E-21"
        iyy="7.03620982427167E-05"
        iyz="1.67632102109803E-20"
        izz="5.85727895452638E-05" />
    </inertial>
    <visual>
      <origin
        xyz="0 0 0"
        rpy="0 0 0" />
      <geometry>
        <mesh
          filename="package://valter/meshes/lwheel_centers.STL" />
      </geometry>
      <material
        name="">
        <color
          rgba="0.796078431372549 0.823529411764706 0.937254901960784 1" />
      </material>
    </visual>
    <collision>
      <origin
        xyz="0 0 0"
        rpy="0 0 0" />
      <geometry>
        <mesh
          filename="package://valter/meshes/lwheel_centers.STL" />
      </geometry>
    </collision>
  </link>
  <joint
    name="lwheel_centers_fixed"
    type="fixed">
    <origin
      xyz="0 -0.00181724367610836 0"
      rpy="0 -1.66371525153719E-34 0" />
    <parent
      link="LWheel" />
    <child
      link="lwheel_centers" />
    <axis
      xyz="0 1 0" />
  </joint>
  <link
    name="support_wheels">
    <inertial>
      <origin
        xyz="-0.219066879644595 -1.38777878078145E-17 -0.111817164878115"
        rpy="0 0 0" />
      <mass
        value="1.30791131979034" />
      <inertia
        ixx="0.0180362608696526"
        ixy="-1.32542149329189E-18"
        ixz="0"
        iyy="0.0808033145464291"
        iyz="3.38263990177013E-19"
        izz="0.0658583097429299" />
    </inertial>
    <visual>
      <origin
        xyz="0 0 0"
        rpy="0 0 0" />
      <geometry>
        <mesh
          filename="package://valter/meshes/support_wheels.STL" />
      </geometry>
      <material
        name="">
        <color
          rgba="0.250980392156863 0.250980392156863 0.250980392156863 1" />
      </material>
    </visual>
    <collision>
      <origin
        xyz="0 0 0"
        rpy="0 0 0" />
      <geometry>
        <mesh
          filename="package://valter/meshes/support_wheels.STL" />
      </geometry>
    </collision>
  </link>
  <joint
    name="support_wheels_fixed"
    type="fixed">
    <origin
      xyz="0.189234607270609 -0.11129709785824 0.0679256801186866"
      rpy="1.5707963267949 0 0" />
    <parent
      link="Base" />
    <child
      link="support_wheels" />
    <axis
      xyz="0 0 0" />
  </joint>
  <link
    name="support_wheels_centers">
    <inertial>
      <origin
        xyz="-0.219066879644595 1.38777878078145E-17 0.110556114336065"
        rpy="0 0 0" />
      <mass
        value="0.101015328916835" />
      <inertia
        ixx="0.00129045558161767"
        ixy="-9.77029153679058E-20"
        ixz="-3.3881317890172E-19"
        iyy="0.00613821129438006"
        iyz="4.09724133506638E-20"
        izz="0.00487802902064206" />
    </inertial>
    <visual>
      <origin
        xyz="0 0 0"
        rpy="0 0 0" />
      <geometry>
        <mesh
          filename="package://valter/meshes/support_wheels_centers.STL" />
      </geometry>
      <material
        name="">
        <color
          rgba="0.796078431372549 0.823529411764706 0.937254901960784 1" />
      </material>
    </visual>
    <collision>
      <origin
        xyz="0 0 0"
        rpy="0 0 0" />
      <geometry>
        <mesh
          filename="package://valter/meshes/support_wheels_centers.STL" />
      </geometry>
    </collision>
  </link>
  <joint
    name="support_wheels_centers_fixed"
    type="fixed">
    <origin
      xyz="0 0 -0.222438597166117"
      rpy="0 0 0" />
    <parent
      link="support_wheels" />
    <child
      link="support_wheels_centers" />
    <axis
      xyz="0 0 0" />
  </joint>
  <link
    name="ManipulatorBase">
    <inertial>
      <origin
        xyz="0.0757274431880703 -0.00904190076144362 -0.035"
        rpy="0 0 0" />
      <mass
        value="0.178834143520891" />
      <inertia
        ixx="0.000174752266227878"
        ixy="3.75007914498888E-21"
        ixz="-2.30189996267457E-20"
        iyy="0.000407098672925193"
        iyz="3.53103137965607E-21"
        izz="0.000259421347673262" />
    </inertial>
    <visual>
      <origin
        xyz="0 0 0"
        rpy="0 0 0" />
      <geometry>
        <mesh
          filename="package://valter/meshes/ManipulatorBase.STL" />
      </geometry>
      <material
        name="">
        <color
          rgba="0.796078431372549 0.823529411764706 0.937254901960784 1" />
      </material>
    </visual>
    <collision>
      <origin
        xyz="0 0 0"
        rpy="0 0 0" />
      <geometry>
        <mesh
          filename="package://valter/meshes/ManipulatorBase.STL" />
      </geometry>
    </collision>
  </link>
  <joint
    name="ManipulatorBaseFixed"
    type="fixed">
    <origin
      xyz="0.157269945428792 0.0354609509421621 0.707041900761443"
      rpy="1.5707963267949 0 3.14159265358979" />
    <parent
      link="Base" />
    <child
      link="ManipulatorBase" />
    <axis
      xyz="0 0 0" />
  </joint>
  <link
    name="ManipulatorLink1">
    <inertial>
      <origin
        xyz="0.0084271 -0.29887 0.034995"
        rpy="0 0 0" />
      <mass
        value="0.47801" />
      <inertia
        ixx="0.013436"
        ixy="-0.00089216"
        ixz="-1.6445E-10"
        iyy="0.0004086"
        iyz="5.7508E-09"
        izz="0.013731" />
    </inertial>
    <visual>
      <origin
        xyz="0 0 0"
        rpy="0 0 0" />
      <geometry>
        <mesh
          filename="package://valter/meshes/ManipulatorLink1.STL" />
      </geometry>
      <material
        name="">
        <color
          rgba="0.79216 0.81961 0.8 1" />
      </material>
    </visual>
    <collision>
      <origin
        xyz="0 0 0"
        rpy="0 0 0" />
      <geometry>
        <mesh
          filename="package://valter/meshes/ManipulatorLink1.STL" />
      </geometry>
    </collision>
  </link>
  <joint
    name="ManipulatorLink1Axis"
    type="revolute">
    <origin
      xyz="0.015824 -0.0090419 0"
      rpy="3.1416 0 3.1416" />
    <parent
      link="ManipulatorBase" />
    <child
      link="ManipulatorLink1" />
    <axis
      xyz="0 0 -1" />
    <limit
      lower="-1.5"
      upper="0"
      effort="0"
      velocity="0" />
  </joint>
  <link
    name="ManipulatorLink2">
    <inertial>
      <origin
        xyz="-0.0019648 0.34838 0.034995"
        rpy="0 0 0" />
      <mass
        value="0.30452" />
      <inertia
        ixx="0.0077703"
        ixy="-0.00010965"
        ixz="-4.7931E-12"
        iyy="0.000301"
        iyz="2.8093E-10"
        izz="0.007534" />
    </inertial>
    <visual>
      <origin
        xyz="0 0 0"
        rpy="0 0 0" />
      <geometry>
        <mesh
          filename="package://valter/meshes/ManipulatorLink2.STL" />
      </geometry>
      <material
        name="">
        <color
          rgba="0.79216 0.81961 0.7 1" />
      </material>
    </visual>
    <collision>
      <origin
        xyz="0 0 0"
        rpy="0 0 0" />
      <geometry>
        <mesh
          filename="package://valter/meshes/ManipulatorLink2.STL" />
      </geometry>
    </collision>
  </link>
  <joint
    name="ManipulatorLink2Axis"
    type="revolute">
    <origin
      xyz="0.10656 -0.49054 0"
      rpy="0 0 0" />
    <parent
      link="ManipulatorLink1" />
    <child
      link="ManipulatorLink2" />
    <axis
      xyz="0 0 -1" />
    <limit
      lower="0"
      upper="1.5"
      effort="0"
      velocity="0" />
  </joint>
  <link
    name="ManipulatorLink3">
    <inertial>
      <origin
        xyz="-0.0046526 -0.021945 0.034995"
        rpy="0 0 0" />
      <mass
        value="0.22788" />
      <inertia
        ixx="0.00019702"
        ixy="4.0348E-05"
        ixz="-2.4752E-12"
        iyy="0.00015328"
        iyz="3.0548E-12"
        izz="0.00021369" />
    </inertial>
    <visual>
      <origin
        xyz="0 0 0"
        rpy="0 0 0" />
      <geometry>
        <mesh
          filename="package://valter/meshes/ManipulatorLink3.STL" />
      </geometry>
      <material
        name="">
        <color
          rgba="0.32157 0.43137 0.4549 1" />
      </material>
    </visual>
    <collision>
      <origin
        xyz="0 0 0"
        rpy="0 0 0" />
      <geometry>
        <mesh
          filename="package://valter/meshes/ManipulatorLink3.STL" />
      </geometry>
    </collision>
  </link>
  <joint
    name="ManipulatorLink3Axis"
    type="revolute">
    <origin
      xyz="-0.012962 0.55415 0"
      rpy="0 0 0" />
    <parent
      link="ManipulatorLink2" />
    <child
      link="ManipulatorLink3" />
    <axis
      xyz="0 0 -1" />
    <limit
      lower="0"
      upper="1"
      effort="0"
      velocity="0" />
  </joint>
  <link
    name="ManipulatorLink4">
    <inertial>
      <origin
        xyz="-2.2732E-05 0.083954 0"
        rpy="0 0 0" />
      <mass
        value="0.42935" />
      <inertia
        ixx="0.00093594"
        ixy="4.2609E-07"
        ixz="9.132E-21"
        iyy="0.00033918"
        iyz="1.5845E-19"
        izz="0.0010509" />
    </inertial>
    <visual>
      <origin
        xyz="0 0 0"
        rpy="0 0 0" />
      <geometry>
        <mesh
          filename="package://valter/meshes/ManipulatorLink4.STL" />
      </geometry>
      <material
        name="">
        <color
          rgba="0.4 0.82353 0.8 1" />
      </material>
    </visual>
    <collision>
      <origin
        xyz="0 0 0"
        rpy="0 0 0" />
      <geometry>
        <mesh
          filename="package://valter/meshes/ManipulatorLink4.STL" />
      </geometry>
    </collision>
  </link>
  <joint
    name="ManipulatorLink4Axis"
    type="revolute">
    <origin
      xyz="0 0.008 0.034995"
      rpy="0 1.5708 0" />
    <parent
      link="ManipulatorLink3" />
    <child
      link="ManipulatorLink4" />
    <axis
      xyz="0 -1 0" />
    <limit
      lower="-3"
      upper="3"
      effort="0"
      velocity="0" />
  </joint>
  <link
    name="GripperL">
    <inertial>
      <origin
        xyz="0.0029778 0.087145 -0.0098651"
        rpy="0 0 0" />
      <mass
        value="0.039858" />
      <inertia
        ixx="0.00010179"
        ixy="-4.7356E-06"
        ixz="-2.1627E-22"
        iyy="2.3271E-06"
        iyz="1.1485E-21"
        izz="0.00010172" />
    </inertial>
    <visual>
      <origin
        xyz="0 0 0"
        rpy="0 0 0" />
      <geometry>
        <mesh
          filename="package://valter/meshes/GripperL.STL" />
      </geometry>
      <material
        name="">
        <color
          rgba="0.15686 0.15686 0.15686 1" />
      </material>
    </visual>
    <collision>
      <origin
        xyz="0 0 0"
        rpy="0 0 0" />
      <geometry>
        <mesh
          filename="package://valter/meshes/GripperL.STL" />
      </geometry>
    </collision>
  </link>
  <joint
    name="GripperLAxis"
    type="prismatic">
    <origin
      xyz="0.049892 0.090686 -0.0096825"
      rpy="3.1416 -6.9389E-17 -3.1416" />
    <parent
      link="ManipulatorLink4" />
    <child
      link="GripperL" />
    <axis
      xyz="-1 0 0" />
    <limit
      lower="-0.03"
      upper="0"
      effort="0"
      velocity="0" />
  </joint>
  <link
    name="GripperR">
    <inertial>
      <origin
        xyz="0.0029778 0.087145 0.0098651"
        rpy="0 0 0" />
      <mass
        value="0.039858" />
      <inertia
        ixx="0.00010179"
        ixy="-4.7356E-06"
        ixz="2.1438E-23"
        iyy="2.3271E-06"
        iyz="-1.4599E-21"
        izz="0.00010172" />
    </inertial>
    <visual>
      <origin
        xyz="0 0 0"
        rpy="0 0 0" />
      <geometry>
        <mesh
          filename="package://valter/meshes/GripperR.STL" />
      </geometry>
      <material
        name="">
        <color
          rgba="0.15686 0.15686 0.15686 1" />
      </material>
    </visual>
    <collision>
      <origin
        xyz="0 0 0"
        rpy="0 0 0" />
      <geometry>
        <mesh
          filename="package://valter/meshes/GripperR.STL" />
      </geometry>
    </collision>
  </link>
  <joint
    name="GripperRAxis"
    type="prismatic">
    <origin
      xyz="-0.049892 0.090686 -0.0096825"
      rpy="-4.9087E-21 6.9389E-17 1.0613E-16" />
    <parent
      link="ManipulatorLink4" />
    <child
      link="GripperR" />
    <axis
      xyz="1 0 0" />
    <limit
      lower="0"
      upper="0.03"
      effort="0"
      velocity="0" />
  </joint>
</robot>