<robot
  name="valter">
  <link
    name="Base">
    <inertial>
      <origin
        xyz="-0.0847783141108011 0.00202029809854648 0.418887021717725"
        rpy="0 0 0" />
      <mass
        value="12.6713271850958" />
      <inertia
        ixx="0.626766592614186"
        ixy="0.00682598684505572"
        ixz="-0.0769516766880175"
        iyy="0.921731144328388"
        iyz="0.000850752893155058"
        izz="0.638669203522036" />
    </inertial>
    <visual>
      <origin
        xyz="0 0 0"
        rpy="0 0 0" />
      <geometry>
        <mesh
          filename="package://valter/meshes/Base.STL" />
      </geometry>
      <material
        name="">
        <color
          rgba="0.796078431372549 0.823529411764706 0.937254901960784 1" />
      </material>
    </visual>
    <collision>
      <origin
        xyz="0 0 0"
        rpy="0 0 0" />
      <geometry>
        <mesh
          filename="package://valter/meshes/Base.STL" />
      </geometry>
    </collision>
  </link>
  <link
    name="RWheel">
    <inertial>
      <origin
        xyz="-5.80048162279745E-18 -0.0398900576381727 2.77555756156289E-17"
        rpy="0 0 0" />
      <mass
        value="3.69869087372323" />
      <inertia
        ixx="0.0207205410121268"
        ixy="1.47603546346958E-19"
        ixz="-6.74972677106596E-22"
        iyy="0.0379550554708278"
        iyz="-5.13134781883054E-21"
        izz="0.0207205410121268" />
    </inertial>
    <visual>
      <origin
        xyz="0 0 0"
        rpy="0 0 0" />
      <geometry>
        <mesh
          filename="package://valter/meshes/RWheel.STL" />
      </geometry>
      <material
        name="">
        <color
          rgba="0.796078431372549 0.823529411764706 0.937254901960784 1" />
      </material>
    </visual>
    <collision>
      <origin
        xyz="0 0 0"
        rpy="0 0 0" />
      <geometry>
        <mesh
          filename="package://valter/meshes/RWheel.STL" />
      </geometry>
    </collision>
  </link>
  <joint
    name="RWheelAxis"
    type="continuous">
    <origin
      xyz="0.00034158 -0.15368 0.14"
      rpy="-6.123E-17 0 0" />
    <parent
      link="Base" />
    <child
      link="RWheel" />
    <axis
      xyz="0 1 0" />
    <limit
      effort="0"
      velocity="0" />
  </joint>
  <link
    name="LWheel">
    <inertial>
      <origin
        xyz="-2.77555756156289E-17 -0.0398900576381727 2.77555756156289E-17"
        rpy="0 0 0" />
      <mass
        value="3.69869087372323" />
      <inertia
        ixx="0.0207205410121268"
        ixy="-3.59293126057456E-19"
        ixz="-4.33680868994202E-19"
        iyy="0.0379550554708278"
        iyz="-7.65532753262813E-20"
        izz="0.0207205410121268" />
    </inertial>
    <visual>
      <origin
        xyz="0 0 0"
        rpy="0 0 0" />
      <geometry>
        <mesh
          filename="package://valter/meshes/LWheel.STL" />
      </geometry>
      <material
        name="">
        <color
          rgba="0.796078431372549 0.823529411764706 0.937254901960784 1" />
      </material>
    </visual>
    <collision>
      <origin
        xyz="0 0 0"
        rpy="0 0 0" />
      <geometry>
        <mesh
          filename="package://valter/meshes/LWheel.STL" />
      </geometry>
    </collision>
  </link>
  <joint
    name="LWheelAxis"
    type="continuous">
    <origin
      xyz="0.00034158 0.15432 0.14"
      rpy="6.6286E-17 0.39309 -3.1416" />
    <parent
      link="Base" />
    <child
      link="LWheel" />
    <axis
      xyz="0 -1 0" />
  </joint>
  <link
    name="support_wheels">
    <inertial>
      <origin
        xyz="-0.219066879644595 -1.38777878078145E-17 -0.111817164878115"
        rpy="0 0 0" />
      <mass
        value="1.30791131979034" />
      <inertia
        ixx="0.0180362608696526"
        ixy="-2.31948761326081E-18"
        ixz="-1.73472347597681E-18"
        iyy="0.0808033145464291"
        iyz="-1.69131995088506E-19"
        izz="0.0658583097429299" />
    </inertial>
    <visual>
      <origin
        xyz="0 0 0"
        rpy="0 0 0" />
      <geometry>
        <mesh
          filename="package://valter/meshes/support_wheels.STL" />
      </geometry>
      <material
        name="">
        <color
          rgba="0.250980392156863 0.250980392156863 0.250980392156863 1" />
      </material>
    </visual>
    <collision>
      <origin
        xyz="0 0 0"
        rpy="0 0 0" />
      <geometry>
        <mesh
          filename="package://valter/meshes/support_wheels.STL" />
      </geometry>
    </collision>
  </link>
  <joint
    name="support_wheels_fixed"
    type="fixed">
    <origin
      xyz="0.18923 -0.1113 0.067926"
      rpy="1.5708 0 0" />
    <parent
      link="Base" />
    <child
      link="support_wheels" />
    <axis
      xyz="0 0 0" />
  </joint>
  <link
    name="support_wheels_centers">
    <inertial>
      <origin
        xyz="-0.219066879644595 0 0.110556114336065"
        rpy="0 0 0" />
      <mass
        value="0.101015328916835" />
      <inertia
        ixx="0.00129045558161767"
        ixy="-3.60504693634201E-20"
        ixz="-2.98155597433514E-19"
        iyy="0.00613821129438006"
        iyz="-5.86188037126275E-20"
        izz="0.00487802902064206" />
    </inertial>
    <visual>
      <origin
        xyz="0 0 0"
        rpy="0 0 0" />
      <geometry>
        <mesh
          filename="package://valter/meshes/support_wheels_centers.STL" />
      </geometry>
      <material
        name="">
        <color
          rgba="0.796078431372549 0.823529411764706 0.937254901960784 1" />
      </material>
    </visual>
    <collision>
      <origin
        xyz="0 0 0"
        rpy="0 0 0" />
      <geometry>
        <mesh
          filename="package://valter/meshes/support_wheels_centers.STL" />
      </geometry>
    </collision>
  </link>
  <joint
    name="support_wheels_centers_fixed"
    type="fixed">
    <origin
      xyz="0 0 -0.22244"
      rpy="0 0 0" />
    <parent
      link="support_wheels" />
    <child
      link="support_wheels_centers" />
    <axis
      xyz="0 0 0" />
  </joint>
</robot>